2024-12-24 12:30:09 - Virtual environment is not activated. Choosing activation script...
2024-12-24 12:30:11 - Running application...
NoneType: None
NoneType: None
['lcolonq', 'crudeirc']
Connecting to colonq.computer on port 26697
colonq.computer 26697
2024-12-24 12:30:36 - Application finished. Waiting for user input before exiting...
2024-12-24 12:30:37 - User pressed Enter. Exiting...
2024-12-24 12:30:38 - Virtual environment is not activated. Choosing activation script...
2024-12-24 12:30:39 - Running application...
Exception in Tkinter callback
Traceback (most recent call last):
  File "/home/retro/Documents/crudeirc/crudeirc.py", line 615, in connect
    self.irc_socket = context.wrap_socket(
                      ^^^^^^^^^^^^^^^^^^^^
  File "/usr/lib/python3.12/ssl.py", line 455, in wrap_socket
    return self.sslsocket_class._create(
           ^^^^^^^^^^^^^^^^^^^^^^^^^^^^^
  File "/usr/lib/python3.12/ssl.py", line 1042, in _create
    self.do_handshake()
  File "/usr/lib/python3.12/ssl.py", line 1320, in do_handshake
    self._sslobj.do_handshake()
ssl.SSLCertVerificationError: [SSL: CERTIFICATE_VERIFY_FAILED] certificate verify failed: self-signed certificate (_ssl.c:1000)

During handling of the above exception, another exception occurred:

Traceback (most recent call last):
  File "/usr/lib/python3.12/tkinter/__init__.py", line 1967, in __call__
    return self.func(*args)
           ^^^^^^^^^^^^^^^^
  File "/home/retro/Documents/crudeirc/crudeirc.py", line 552, in toggle_connection
    self.connect()
  File "/home/retro/Documents/crudeirc/crudeirc.py", line 632, in connect
    traceback.print_exc(e)
  File "/usr/lib/python3.12/traceback.py", line 180, in print_exc
    print_exception(sys.exception(), limit=limit, file=file, chain=chain)
  File "/usr/lib/python3.12/traceback.py", line 124, in print_exception
    te = TracebackException(type(value), value, tb, limit=limit, compact=True)
         ^^^^^^^^^^^^^^^^^^^^^^^^^^^^^^^^^^^^^^^^^^^^^^^^^^^^^^^^^^^^^^^^^^^^^
  File "/usr/lib/python3.12/traceback.py", line 733, in __init__
    self.stack = StackSummary._extract_from_extended_frame_gen(
                 ^^^^^^^^^^^^^^^^^^^^^^^^^^^^^^^^^^^^^^^^^^^^^^
  File "/usr/lib/python3.12/traceback.py", line 411, in _extract_from_extended_frame_gen
    if limit >= 0:
       ^^^^^^^^^^
TypeError: '>=' not supported between instances of 'SSLCertVerificationError' and 'int'
Exception in Tkinter callback
Traceback (most recent call last):
  File "/home/retro/Documents/crudeirc/crudeirc.py", line 615, in connect
    self.irc_socket = context.wrap_socket(
                      ^^^^^^^^^^^^^^^^^^^^
  File "/usr/lib/python3.12/ssl.py", line 455, in wrap_socket
    return self.sslsocket_class._create(
           ^^^^^^^^^^^^^^^^^^^^^^^^^^^^^
  File "/usr/lib/python3.12/ssl.py", line 1042, in _create
    self.do_handshake()
  File "/usr/lib/python3.12/ssl.py", line 1320, in do_handshake
    self._sslobj.do_handshake()
ssl.SSLCertVerificationError: [SSL: CERTIFICATE_VERIFY_FAILED] certificate verify failed: self-signed certificate (_ssl.c:1000)

During handling of the above exception, another exception occurred:

Traceback (most recent call last):
  File "/usr/lib/python3.12/tkinter/__init__.py", line 1967, in __call__
    return self.func(*args)
           ^^^^^^^^^^^^^^^^
  File "/home/retro/Documents/crudeirc/crudeirc.py", line 552, in toggle_connection
    self.connect()
  File "/home/retro/Documents/crudeirc/crudeirc.py", line 632, in connect
    traceback.print_exc(e)
  File "/usr/lib/python3.12/traceback.py", line 180, in print_exc
    print_exception(sys.exception(), limit=limit, file=file, chain=chain)
  File "/usr/lib/python3.12/traceback.py", line 124, in print_exception
    te = TracebackException(type(value), value, tb, limit=limit, compact=True)
         ^^^^^^^^^^^^^^^^^^^^^^^^^^^^^^^^^^^^^^^^^^^^^^^^^^^^^^^^^^^^^^^^^^^^^
  File "/usr/lib/python3.12/traceback.py", line 733, in __init__
    self.stack = StackSummary._extract_from_extended_frame_gen(
                 ^^^^^^^^^^^^^^^^^^^^^^^^^^^^^^^^^^^^^^^^^^^^^^
  File "/usr/lib/python3.12/traceback.py", line 411, in _extract_from_extended_frame_gen
    if limit >= 0:
       ^^^^^^^^^^
TypeError: '>=' not supported between instances of 'SSLCertVerificationError' and 'int'
['lcolonq', 'crudeirc']
Connecting to crudeserver.duckdns.org on port 6697
crudeserver.duckdns.org 6697
Connecting to crudeserver.duckdns.org on port 6697
crudeserver.duckdns.org 6697
2024-12-24 12:32:39 - Application finished. Waiting for user input before exiting...
2024-12-24 12:32:40 - User pressed Enter. Exiting...
2024-12-24 12:33:22 - Virtual environment is not activated. Choosing activation script...
2024-12-24 12:33:24 - Running application...
Exception in Tkinter callback
Traceback (most recent call last):
  File "/home/retro/Documents/crudeirc/crudeirc.py", line 610, in connect
    self.irc_socket.connect((self.server, int(self.port)))
ConnectionRefusedError: [Errno 111] Connection refused

During handling of the above exception, another exception occurred:

Traceback (most recent call last):
  File "/usr/lib/python3.12/tkinter/__init__.py", line 1967, in __call__
    return self.func(*args)
           ^^^^^^^^^^^^^^^^
  File "/home/retro/Documents/crudeirc/crudeirc.py", line 552, in toggle_connection
    self.connect()
  File "/home/retro/Documents/crudeirc/crudeirc.py", line 632, in connect
    traceback.print_exc(e)
  File "/usr/lib/python3.12/traceback.py", line 180, in print_exc
    print_exception(sys.exception(), limit=limit, file=file, chain=chain)
  File "/usr/lib/python3.12/traceback.py", line 124, in print_exception
    te = TracebackException(type(value), value, tb, limit=limit, compact=True)
         ^^^^^^^^^^^^^^^^^^^^^^^^^^^^^^^^^^^^^^^^^^^^^^^^^^^^^^^^^^^^^^^^^^^^^
  File "/usr/lib/python3.12/traceback.py", line 733, in __init__
    self.stack = StackSummary._extract_from_extended_frame_gen(
                 ^^^^^^^^^^^^^^^^^^^^^^^^^^^^^^^^^^^^^^^^^^^^^^
  File "/usr/lib/python3.12/traceback.py", line 411, in _extract_from_extended_frame_gen
    if limit >= 0:
       ^^^^^^^^^^
TypeError: '>=' not supported between instances of 'ConnectionRefusedError' and 'int'
Exception in Tkinter callback
Traceback (most recent call last):
  File "/home/retro/Documents/crudeirc/crudeirc.py", line 615, in connect
    self.irc_socket = context.wrap_socket(
                      ^^^^^^^^^^^^^^^^^^^^
  File "/usr/lib/python3.12/ssl.py", line 455, in wrap_socket
    return self.sslsocket_class._create(
           ^^^^^^^^^^^^^^^^^^^^^^^^^^^^^
  File "/usr/lib/python3.12/ssl.py", line 1042, in _create
    self.do_handshake()
  File "/usr/lib/python3.12/ssl.py", line 1320, in do_handshake
    self._sslobj.do_handshake()
ssl.SSLCertVerificationError: [SSL: CERTIFICATE_VERIFY_FAILED] certificate verify failed: self-signed certificate (_ssl.c:1000)

During handling of the above exception, another exception occurred:

Traceback (most recent call last):
  File "/usr/lib/python3.12/tkinter/__init__.py", line 1967, in __call__
    return self.func(*args)
           ^^^^^^^^^^^^^^^^
  File "/home/retro/Documents/crudeirc/crudeirc.py", line 552, in toggle_connection
    self.connect()
  File "/home/retro/Documents/crudeirc/crudeirc.py", line 632, in connect
    traceback.print_exc(e)
  File "/usr/lib/python3.12/traceback.py", line 180, in print_exc
    print_exception(sys.exception(), limit=limit, file=file, chain=chain)
  File "/usr/lib/python3.12/traceback.py", line 124, in print_exception
    te = TracebackException(type(value), value, tb, limit=limit, compact=True)
         ^^^^^^^^^^^^^^^^^^^^^^^^^^^^^^^^^^^^^^^^^^^^^^^^^^^^^^^^^^^^^^^^^^^^^
  File "/usr/lib/python3.12/traceback.py", line 733, in __init__
    self.stack = StackSummary._extract_from_extended_frame_gen(
                 ^^^^^^^^^^^^^^^^^^^^^^^^^^^^^^^^^^^^^^^^^^^^^^
  File "/usr/lib/python3.12/traceback.py", line 411, in _extract_from_extended_frame_gen
    if limit >= 0:
       ^^^^^^^^^^
TypeError: '>=' not supported between instances of 'SSLCertVerificationError' and 'int'
Exception in Tkinter callback
Traceback (most recent call last):
  File "/home/retro/Documents/crudeirc/crudeirc.py", line 610, in connect
    self.irc_socket.connect((self.server, int(self.port)))
ConnectionRefusedError: [Errno 111] Connection refused

During handling of the above exception, another exception occurred:

Traceback (most recent call last):
  File "/usr/lib/python3.12/tkinter/__init__.py", line 1967, in __call__
    return self.func(*args)
           ^^^^^^^^^^^^^^^^
  File "/home/retro/Documents/crudeirc/crudeirc.py", line 552, in toggle_connection
    self.connect()
  File "/home/retro/Documents/crudeirc/crudeirc.py", line 632, in connect
    traceback.print_exc(e)
  File "/usr/lib/python3.12/traceback.py", line 180, in print_exc
    print_exception(sys.exception(), limit=limit, file=file, chain=chain)
  File "/usr/lib/python3.12/traceback.py", line 124, in print_exception
    te = TracebackException(type(value), value, tb, limit=limit, compact=True)
         ^^^^^^^^^^^^^^^^^^^^^^^^^^^^^^^^^^^^^^^^^^^^^^^^^^^^^^^^^^^^^^^^^^^^^
  File "/usr/lib/python3.12/traceback.py", line 733, in __init__
    self.stack = StackSummary._extract_from_extended_frame_gen(
                 ^^^^^^^^^^^^^^^^^^^^^^^^^^^^^^^^^^^^^^^^^^^^^^
  File "/usr/lib/python3.12/traceback.py", line 411, in _extract_from_extended_frame_gen
    if limit >= 0:
       ^^^^^^^^^^
TypeError: '>=' not supported between instances of 'ConnectionRefusedError' and 'int'
Exception in Tkinter callback
Traceback (most recent call last):
  File "/home/retro/Documents/crudeirc/crudeirc.py", line 610, in connect
    self.irc_socket.connect((self.server, int(self.port)))
ConnectionRefusedError: [Errno 111] Connection refused

During handling of the above exception, another exception occurred:

Traceback (most recent call last):
  File "/usr/lib/python3.12/tkinter/__init__.py", line 1967, in __call__
    return self.func(*args)
           ^^^^^^^^^^^^^^^^
  File "/home/retro/Documents/crudeirc/crudeirc.py", line 552, in toggle_connection
    self.connect()
  File "/home/retro/Documents/crudeirc/crudeirc.py", line 632, in connect
    traceback.print_exc(e)
  File "/usr/lib/python3.12/traceback.py", line 180, in print_exc
    print_exception(sys.exception(), limit=limit, file=file, chain=chain)
  File "/usr/lib/python3.12/traceback.py", line 124, in print_exception
    te = TracebackException(type(value), value, tb, limit=limit, compact=True)
         ^^^^^^^^^^^^^^^^^^^^^^^^^^^^^^^^^^^^^^^^^^^^^^^^^^^^^^^^^^^^^^^^^^^^^
  File "/usr/lib/python3.12/traceback.py", line 733, in __init__
    self.stack = StackSummary._extract_from_extended_frame_gen(
                 ^^^^^^^^^^^^^^^^^^^^^^^^^^^^^^^^^^^^^^^^^^^^^^
  File "/usr/lib/python3.12/traceback.py", line 411, in _extract_from_extended_frame_gen
    if limit >= 0:
       ^^^^^^^^^^
TypeError: '>=' not supported between instances of 'ConnectionRefusedError' and 'int'
Exception in Tkinter callback
Traceback (most recent call last):
  File "/home/retro/Documents/crudeirc/crudeirc.py", line 615, in connect
    self.irc_socket = context.wrap_socket(
                      ^^^^^^^^^^^^^^^^^^^^
  File "/usr/lib/python3.12/ssl.py", line 455, in wrap_socket
    return self.sslsocket_class._create(
           ^^^^^^^^^^^^^^^^^^^^^^^^^^^^^
  File "/usr/lib/python3.12/ssl.py", line 1042, in _create
    self.do_handshake()
  File "/usr/lib/python3.12/ssl.py", line 1320, in do_handshake
    self._sslobj.do_handshake()
ssl.SSLCertVerificationError: [SSL: CERTIFICATE_VERIFY_FAILED] certificate verify failed: self-signed certificate (_ssl.c:1000)

During handling of the above exception, another exception occurred:

Traceback (most recent call last):
  File "/usr/lib/python3.12/tkinter/__init__.py", line 1967, in __call__
    return self.func(*args)
           ^^^^^^^^^^^^^^^^
  File "/home/retro/Documents/crudeirc/crudeirc.py", line 552, in toggle_connection
    self.connect()
  File "/home/retro/Documents/crudeirc/crudeirc.py", line 632, in connect
    traceback.print_exc(e)
  File "/usr/lib/python3.12/traceback.py", line 180, in print_exc
    print_exception(sys.exception(), limit=limit, file=file, chain=chain)
  File "/usr/lib/python3.12/traceback.py", line 124, in print_exception
    te = TracebackException(type(value), value, tb, limit=limit, compact=True)
         ^^^^^^^^^^^^^^^^^^^^^^^^^^^^^^^^^^^^^^^^^^^^^^^^^^^^^^^^^^^^^^^^^^^^^
  File "/usr/lib/python3.12/traceback.py", line 733, in __init__
    self.stack = StackSummary._extract_from_extended_frame_gen(
                 ^^^^^^^^^^^^^^^^^^^^^^^^^^^^^^^^^^^^^^^^^^^^^^
  File "/usr/lib/python3.12/traceback.py", line 411, in _extract_from_extended_frame_gen
    if limit >= 0:
       ^^^^^^^^^^
TypeError: '>=' not supported between instances of 'SSLCertVerificationError' and 'int'
Exception in Tkinter callback
Traceback (most recent call last):
  File "/home/retro/Documents/crudeirc/crudeirc.py", line 610, in connect
    self.irc_socket.connect((self.server, int(self.port)))
ConnectionRefusedError: [Errno 111] Connection refused

During handling of the above exception, another exception occurred:

Traceback (most recent call last):
  File "/usr/lib/python3.12/tkinter/__init__.py", line 1967, in __call__
    return self.func(*args)
           ^^^^^^^^^^^^^^^^
  File "/home/retro/Documents/crudeirc/crudeirc.py", line 552, in toggle_connection
    self.connect()
  File "/home/retro/Documents/crudeirc/crudeirc.py", line 632, in connect
    traceback.print_exc(e)
  File "/usr/lib/python3.12/traceback.py", line 180, in print_exc
    print_exception(sys.exception(), limit=limit, file=file, chain=chain)
  File "/usr/lib/python3.12/traceback.py", line 124, in print_exception
    te = TracebackException(type(value), value, tb, limit=limit, compact=True)
         ^^^^^^^^^^^^^^^^^^^^^^^^^^^^^^^^^^^^^^^^^^^^^^^^^^^^^^^^^^^^^^^^^^^^^
  File "/usr/lib/python3.12/traceback.py", line 733, in __init__
    self.stack = StackSummary._extract_from_extended_frame_gen(
                 ^^^^^^^^^^^^^^^^^^^^^^^^^^^^^^^^^^^^^^^^^^^^^^
  File "/usr/lib/python3.12/traceback.py", line 411, in _extract_from_extended_frame_gen
    if limit >= 0:
       ^^^^^^^^^^
TypeError: '>=' not supported between instances of 'ConnectionRefusedError' and 'int'
Connecting to crudeserver.duckdns.org on port 6697
crudeserver.duckdns.org 6697
['lcolonq', 'crudeirc']
['lcolonq', 'crudeirc']
['lcolonq', 'crudeirc']
Connecting to crudeserver.duckdns.org on port 6697
crudeserver.duckdns.org 6697
['lcolonq', 'crudeirc']
Connecting to crudeserver.duckdns.org on port 6697
crudeserver.duckdns.org 6697
['lcolonq', 'crudeirc']
Connecting to crudeserver.duckdns.org on port 6697
crudeserver.duckdns.org 6697
['lcolonq', 'crudeirc']
Connecting to crudeserver.duckdns.org on port 6697
crudeserver.duckdns.org 6697
Connecting to crudeserver.duckdns.org on port 6697
crudeserver.duckdns.org 6697
2024-12-24 13:09:35 - Application finished. Waiting for user input before exiting...
2024-12-24 13:53:09 - User pressed Enter. Exiting...
