2024-12-23 20:13:27 - Virtual environment is not activated. Choosing activation script...
2024-12-23 20:13:28 - Running application...
Exception in Tkinter callback
Traceback (most recent call last):
  File "/usr/lib/python3.12/tkinter/__init__.py", line 1967, in __call__
    return self.func(*args)
           ^^^^^^^^^^^^^^^^
  File "/home/retro/Documents/crudeirc/crudeirc.py", line 552, in toggle_connection
    self.connect()
  File "/home/retro/Documents/crudeirc/crudeirc.py", line 610, in connect
    self.irc_socket.connect((self.server, int(self.port)))
KeyboardInterrupt
2024-12-23 20:18:18 - Virtual environment is not activated. Choosing activation script...
2024-12-23 20:18:19 - Running application...
2024-12-23 20:24:00 - Virtual environment is not activated. Choosing activation script...
2024-12-23 20:24:02 - Running application...
2024-12-23 20:25:18 - Virtual environment is not activated. Choosing activation script...
2024-12-23 20:25:19 - Running application...
2024-12-23 20:31:46 - Virtual environment is not activated. Choosing activation script...
2024-12-23 20:31:48 - Running application...
2024-12-23 20:46:36 - Virtual environment is not activated. Choosing activation script...
2024-12-23 20:46:37 - Running application...
Exception in Tkinter callback
Traceback (most recent call last):
  File "/home/retro/Documents/crudeirc/crudeirc.py", line 615, in connect
    self.irc_socket = context.wrap_socket(
                      ^^^^^^^^^^^^^^^^^^^^
  File "/usr/lib/python3.12/ssl.py", line 455, in wrap_socket
    return self.sslsocket_class._create(
           ^^^^^^^^^^^^^^^^^^^^^^^^^^^^^
  File "/usr/lib/python3.12/ssl.py", line 1042, in _create
    self.do_handshake()
  File "/usr/lib/python3.12/ssl.py", line 1320, in do_handshake
    self._sslobj.do_handshake()
ssl.SSLCertVerificationError: [SSL: CERTIFICATE_VERIFY_FAILED] certificate verify failed: self-signed certificate (_ssl.c:1000)

During handling of the above exception, another exception occurred:

Traceback (most recent call last):
  File "/usr/lib/python3.12/tkinter/__init__.py", line 1967, in __call__
    return self.func(*args)
           ^^^^^^^^^^^^^^^^
  File "/home/retro/Documents/crudeirc/crudeirc.py", line 552, in toggle_connection
    self.connect()
  File "/home/retro/Documents/crudeirc/crudeirc.py", line 632, in connect
    traceback.print_exc(e)
  File "/usr/lib/python3.12/traceback.py", line 180, in print_exc
    print_exception(sys.exception(), limit=limit, file=file, chain=chain)
  File "/usr/lib/python3.12/traceback.py", line 124, in print_exception
    te = TracebackException(type(value), value, tb, limit=limit, compact=True)
         ^^^^^^^^^^^^^^^^^^^^^^^^^^^^^^^^^^^^^^^^^^^^^^^^^^^^^^^^^^^^^^^^^^^^^
  File "/usr/lib/python3.12/traceback.py", line 733, in __init__
    self.stack = StackSummary._extract_from_extended_frame_gen(
                 ^^^^^^^^^^^^^^^^^^^^^^^^^^^^^^^^^^^^^^^^^^^^^^
  File "/usr/lib/python3.12/traceback.py", line 411, in _extract_from_extended_frame_gen
    if limit >= 0:
       ^^^^^^^^^^
TypeError: '>=' not supported between instances of 'SSLCertVerificationError' and 'int'
Exception in Tkinter callback
Traceback (most recent call last):
  File "/home/retro/Documents/crudeirc/crudeirc.py", line 615, in connect
    self.irc_socket = context.wrap_socket(
                      ^^^^^^^^^^^^^^^^^^^^
  File "/usr/lib/python3.12/ssl.py", line 455, in wrap_socket
    return self.sslsocket_class._create(
           ^^^^^^^^^^^^^^^^^^^^^^^^^^^^^
  File "/usr/lib/python3.12/ssl.py", line 1042, in _create
    self.do_handshake()
  File "/usr/lib/python3.12/ssl.py", line 1320, in do_handshake
    self._sslobj.do_handshake()
ssl.SSLCertVerificationError: [SSL: CERTIFICATE_VERIFY_FAILED] certificate verify failed: self-signed certificate (_ssl.c:1000)

During handling of the above exception, another exception occurred:

Traceback (most recent call last):
  File "/usr/lib/python3.12/tkinter/__init__.py", line 1967, in __call__
    return self.func(*args)
           ^^^^^^^^^^^^^^^^
  File "/home/retro/Documents/crudeirc/crudeirc.py", line 552, in toggle_connection
    self.connect()
  File "/home/retro/Documents/crudeirc/crudeirc.py", line 632, in connect
    traceback.print_exc(e)
  File "/usr/lib/python3.12/traceback.py", line 180, in print_exc
    print_exception(sys.exception(), limit=limit, file=file, chain=chain)
  File "/usr/lib/python3.12/traceback.py", line 124, in print_exception
    te = TracebackException(type(value), value, tb, limit=limit, compact=True)
         ^^^^^^^^^^^^^^^^^^^^^^^^^^^^^^^^^^^^^^^^^^^^^^^^^^^^^^^^^^^^^^^^^^^^^
  File "/usr/lib/python3.12/traceback.py", line 733, in __init__
    self.stack = StackSummary._extract_from_extended_frame_gen(
                 ^^^^^^^^^^^^^^^^^^^^^^^^^^^^^^^^^^^^^^^^^^^^^^
  File "/usr/lib/python3.12/traceback.py", line 411, in _extract_from_extended_frame_gen
    if limit >= 0:
       ^^^^^^^^^^
TypeError: '>=' not supported between instances of 'SSLCertVerificationError' and 'int'
['lcolonq', 'crudeirc']
Connecting to crudeserver.duckdns.org on port 6697
crudeserver.duckdns.org 6697
Connecting to crudeserver.duckdns.org on port 6697
crudeserver.duckdns.org 6697
2024-12-23 20:48:36 - Application finished. Waiting for user input before exiting...
2024-12-23 20:48:38 - User pressed Enter. Exiting...
2024-12-23 20:51:08 - Virtual environment is not activated. Choosing activation script...
2024-12-23 20:51:09 - Running application...
Exception in Tkinter callback
Traceback (most recent call last):
  File "/home/retro/Documents/crudeirc/crudeirc.py", line 615, in connect
    self.irc_socket = context.wrap_socket(
                      ^^^^^^^^^^^^^^^^^^^^
  File "/usr/lib/python3.12/ssl.py", line 455, in wrap_socket
    return self.sslsocket_class._create(
           ^^^^^^^^^^^^^^^^^^^^^^^^^^^^^
  File "/usr/lib/python3.12/ssl.py", line 1042, in _create
    self.do_handshake()
  File "/usr/lib/python3.12/ssl.py", line 1320, in do_handshake
    self._sslobj.do_handshake()
ssl.SSLCertVerificationError: [SSL: CERTIFICATE_VERIFY_FAILED] certificate verify failed: self-signed certificate (_ssl.c:1000)

During handling of the above exception, another exception occurred:

Traceback (most recent call last):
  File "/usr/lib/python3.12/tkinter/__init__.py", line 1967, in __call__
    return self.func(*args)
           ^^^^^^^^^^^^^^^^
  File "/home/retro/Documents/crudeirc/crudeirc.py", line 552, in toggle_connection
    self.connect()
  File "/home/retro/Documents/crudeirc/crudeirc.py", line 632, in connect
    traceback.print_exc(e)
  File "/usr/lib/python3.12/traceback.py", line 180, in print_exc
    print_exception(sys.exception(), limit=limit, file=file, chain=chain)
  File "/usr/lib/python3.12/traceback.py", line 124, in print_exception
    te = TracebackException(type(value), value, tb, limit=limit, compact=True)
         ^^^^^^^^^^^^^^^^^^^^^^^^^^^^^^^^^^^^^^^^^^^^^^^^^^^^^^^^^^^^^^^^^^^^^
  File "/usr/lib/python3.12/traceback.py", line 733, in __init__
    self.stack = StackSummary._extract_from_extended_frame_gen(
                 ^^^^^^^^^^^^^^^^^^^^^^^^^^^^^^^^^^^^^^^^^^^^^^
  File "/usr/lib/python3.12/traceback.py", line 411, in _extract_from_extended_frame_gen
    if limit >= 0:
       ^^^^^^^^^^
TypeError: '>=' not supported between instances of 'SSLCertVerificationError' and 'int'
Exception in Tkinter callback
Traceback (most recent call last):
  File "/usr/lib/python3.12/tkinter/__init__.py", line 1967, in __call__
    return self.func(*args)
           ^^^^^^^^^^^^^^^^
  File "/home/retro/Documents/crudeirc/crudeirc.py", line 278, in <lambda>
    self.root.bind("<F5>", lambda e: self.no_distractions())
                                     ^^^^^^^^^^^^^^^^^^^^^^
  File "/home/retro/Documents/crudeirc/crudeirc.py", line 320, in no_distractions
    self.nickname_listbox.pack(side=tk.RIGHT, fill=tk.Y)
  File "/usr/lib/python3.12/tkinter/__init__.py", line 2472, in pack_configure
    self.tk.call(
_tkinter.TclError: cannot use geometry manager pack inside . which already has slaves managed by grid
Exception in Tkinter callback
Traceback (most recent call last):
  File "/usr/lib/python3.12/tkinter/__init__.py", line 1967, in __call__
    return self.func(*args)
           ^^^^^^^^^^^^^^^^
  File "/home/retro/Documents/crudeirc/crudeirc.py", line 278, in <lambda>
    self.root.bind("<F5>", lambda e: self.no_distractions())
                                     ^^^^^^^^^^^^^^^^^^^^^^
  File "/home/retro/Documents/crudeirc/crudeirc.py", line 320, in no_distractions
    self.nickname_listbox.pack(side=tk.RIGHT, fill=tk.Y)
  File "/usr/lib/python3.12/tkinter/__init__.py", line 2472, in pack_configure
    self.tk.call(
_tkinter.TclError: cannot use geometry manager pack inside . which already has slaves managed by grid
Exception in Tkinter callback
Traceback (most recent call last):
  File "/usr/lib/python3.12/tkinter/__init__.py", line 1967, in __call__
    return self.func(*args)
           ^^^^^^^^^^^^^^^^
  File "/home/retro/Documents/crudeirc/crudeirc.py", line 278, in <lambda>
    self.root.bind("<F5>", lambda e: self.no_distractions())
                                     ^^^^^^^^^^^^^^^^^^^^^^
  File "/home/retro/Documents/crudeirc/crudeirc.py", line 320, in no_distractions
    self.nickname_listbox.pack(side=tk.RIGHT, fill=tk.Y)
  File "/usr/lib/python3.12/tkinter/__init__.py", line 2472, in pack_configure
    self.tk.call(
_tkinter.TclError: cannot use geometry manager pack inside . which already has slaves managed by grid
Exception in Tkinter callback
Traceback (most recent call last):
  File "/usr/lib/python3.12/tkinter/__init__.py", line 1967, in __call__
    return self.func(*args)
           ^^^^^^^^^^^^^^^^
  File "/home/retro/Documents/crudeirc/crudeirc.py", line 278, in <lambda>
    self.root.bind("<F5>", lambda e: self.no_distractions())
                                     ^^^^^^^^^^^^^^^^^^^^^^
  File "/home/retro/Documents/crudeirc/crudeirc.py", line 320, in no_distractions
    self.nickname_listbox.pack(side=tk.RIGHT, fill=tk.Y)
  File "/usr/lib/python3.12/tkinter/__init__.py", line 2472, in pack_configure
    self.tk.call(
_tkinter.TclError: cannot use geometry manager pack inside . which already has slaves managed by grid
Exception in Tkinter callback
Traceback (most recent call last):
  File "/usr/lib/python3.12/tkinter/__init__.py", line 1967, in __call__
    return self.func(*args)
           ^^^^^^^^^^^^^^^^
  File "/home/retro/Documents/crudeirc/crudeirc.py", line 278, in <lambda>
    self.root.bind("<F5>", lambda e: self.no_distractions())
                                     ^^^^^^^^^^^^^^^^^^^^^^
  File "/home/retro/Documents/crudeirc/crudeirc.py", line 320, in no_distractions
    self.nickname_listbox.pack(side=tk.RIGHT, fill=tk.Y)
  File "/usr/lib/python3.12/tkinter/__init__.py", line 2472, in pack_configure
    self.tk.call(
_tkinter.TclError: cannot use geometry manager pack inside . which already has slaves managed by grid
Connecting to crudeserver.duckdns.org on port 6697
crudeserver.duckdns.org 6697
['lcolonq', 'crudeirc']
['lcolonq', 'crudeirc']
['lcolonq', 'crudeirc']
['lcolonq', 'crudeirc']
['lcolonq', 'crudeirc']
2024-12-23 22:11:02 - Application finished. Waiting for user input before exiting...
2024-12-23 22:20:42 - User pressed Enter. Exiting...
