2024-12-30 15:04:20 - Virtual environment is not activated. Choosing activation script...
2024-12-30 15:04:21 - Running application...
2024-12-30 15:04:51,163 - INFO - ['lcolonq', 'crudeirc']
Exception in Tkinter callback
Traceback (most recent call last):
  File "asyncio/runners.py", line 118, in run
  File "asyncio/base_events.py", line 687, in run_until_complete
  File "crudetrace.py", line 265, in run_command
  File "asyncio/tasks.py", line 464, in wait
  File "asyncio/tasks.py", line 550, in _wait
asyncio.exceptions.CancelledError

During handling of the above exception, another exception occurred:

Traceback (most recent call last):
  File "tkinter/__init__.py", line 1967, in __call__
  File "crudetrace.py", line 272, in launch_command
  File "asyncio/runners.py", line 194, in run
  File "asyncio/runners.py", line 123, in run
KeyboardInterrupt

During handling of the above exception, another exception occurred:

Traceback (most recent call last):
  File "linecache.py", line 93, in updatecache
FileNotFoundError: [Errno 2] No such file or directory: 'asyncio/runners.py'

During handling of the above exception, another exception occurred:

Traceback (most recent call last):
  File "crudetrace.py", line 601, in <module>
  File "tkinter/__init__.py", line 1504, in mainloop
  File "tkinter/__init__.py", line 1971, in __call__
  File "tkinter/__init__.py", line 1687, in _report_exception
  File "tkinter/__init__.py", line 2426, in report_callback_exception
  File "traceback.py", line 124, in print_exception
  File "traceback.py", line 733, in __init__
  File "traceback.py", line 438, in _extract_from_extended_frame_gen
  File "traceback.py", line 323, in line
  File "linecache.py", line 30, in getline
  File "linecache.py", line 46, in getlines
  File "linecache.py", line 101, in updatecache
  File "PyInstaller/loader/pyimod02_importers.py", line 464, in get_source
  File "PyInstaller/loader/pyimod02_importers.py", line 420, in get_filename
KeyboardInterrupt
[PYI-2772:ERROR] Failed to execute script 'crudetrace' due to unhandled exception!
/home/retro/Documents/crudeirc/config_settings.json
Exception ignored in: <function BaseSubprocessTransport.__del__ at 0x75f67b683920>
Traceback (most recent call last):
  File "asyncio/base_subprocess.py", line 126, in __del__
  File "asyncio/base_subprocess.py", line 104, in close
  File "asyncio/unix_events.py", line 568, in close
  File "asyncio/unix_events.py", line 592, in _close
  File "asyncio/base_events.py", line 795, in call_soon
  File "asyncio/base_events.py", line 541, in _check_closed
RuntimeError: Event loop is closed
2024-12-30 15:05:26 - Application finished. Waiting for user input before exiting...
2024-12-30 15:05:29 - User pressed Enter. Exiting...
